<?xml version="1.0" ?>
<!-- =================================================================================== -->
<!-- |    This document was autogenerated by xacro from /home/uchi/hexapod_ws/src/hexapod_description/urdf/hexapod_description_with_xacro.urdf | -->
<!-- |    EDITING THIS FILE BY HAND IS NOT RECOMMENDED                                 | -->
<!-- =================================================================================== -->
<robot name="hexapod">
  <!-- <link name ="ground">
    <inertial>
      <origin rpy="0 0 0" xyz="0 0 1.0"/>
      <mass value="1"/>
      <inertia ixx="0.3341666666666666" ixy="0.0" ixz="0.0" iyy="0.3341666666666666" iyz="0.0" izz="0.001666666666666667"/>
    </inertial>
  </link>
  <joint name="ground_link" type="floating">
    <origin rpy="0 0 0" xyz="0 0 0.05 "/>
    <parent link="ground"/>
    <child link="body"/>
    <axis xyz="1 1 1"/>
  </joint> -->

  <link name="body">
    <visual>
      <origin rpy="0 0 0" xyz="0 0 0"/>
      <geometry>
        <mesh filename="package://drake/examples/hexapod_drake/mesh/Body.obj"/>
      </geometry>
    </visual>
    <collision>
      <origin rpy="0 0 0" xyz="0 0 0"/>
      <geometry>
        <mesh filename="package://drake/examples/hexapod_drake/mesh/Body.obj"/>
      </geometry>
    </collision>
    <inertial>
      <origin rpy="0 0 0" xyz="-0.001 0.001 -0.003"/>
      <mass value="3.126"/>
      <inertia ixx="0.031" ixy="2.792e-6" ixz="-8.048e-6" iyy="0.017" iyz="-1.53e-5" izz="0.047"/>
    </inertial>
  </link>
  <!--Leg 1 front right-->
  <link name="link1">
    <visual>
      <origin rpy="0 0 0" xyz="0 0 0"/>
      <geometry>
        <mesh filename="package://drake/examples/hexapod_drake/mesh/Link1.obj"/>
      </geometry>
    </visual>
    <collision>
      <origin rpy="0 0 0" xyz="0 0 0"/>
      <geometry>
        <mesh filename="package://drake/examples/hexapod_drake/mesh/Link1.obj"/>
      </geometry>
    </collision>
    <inertial>
      <origin rpy="0 0 0" xyz="-5.5334e-4 0.026044272 5.74418e-4"/>
      <mass value="0.121"/>
      <inertia ixx="5.423e-5" ixy="0" ixz="0" iyy="4.8e-5" iyz="0" izz="5.426e-5"/>
    </inertial>
  </link>
  <joint name="joint1" type="revolute">
    <origin rpy="3.14 0 -0.7853981633974483" xyz="-0.07591 -0.14091 0 "/>
    <parent link="body"/>
    <child link="link1"/>
    <axis xyz="0 0 1"/>
    <limit effort="87" lower="-3.14" upper="3.14" velocity="2.3925"/>
  </joint>
  <transmission name="joint1_trans">
    <type>transmission_interface/SimpleTransmission</type>
    <joint name="joint1">
      <hardwareInterface>EffortJointInterface</hardwareInterface>
    </joint>
    <actuator name="joint1_actuator">
      <hardwareInterface>EffortJointInterface</hardwareInterface>
    </actuator>
  </transmission>

  <link name="link2">
    <visual>
      <origin rpy="0 0 0" xyz="0 0 0"/>
      <geometry>
        <mesh filename="package://drake/examples/hexapod_drake/mesh/Link2.obj"/>
      </geometry>
    </visual>
    <collision>
      <origin rpy="0 0 0" xyz="0 0 0"/>
      <geometry>
        <mesh filename="package://drake/examples/hexapod_drake/mesh/Link2.obj"/>
      </geometry>
    </collision>
    <inertial>
      <origin rpy="0 0 0" xyz="-6.24554e-4 0.019941332 -6.17953e-4"/>
      <mass value="0.43"/>
      <inertia ixx="1.94195e-4" ixy="0" ixz="0" iyy="0.0000912" iyz="0" izz="2.29579e-4"/>
    </inertial>
  </link>
  <joint name="joint2" type="revolute">
    <origin rpy="0.5235987755982988 3.14 0" xyz="0 0.052 0"/>
    <parent link="link1"/>
    <child link="link2"/>
    <axis xyz="1 0 0"/>
    <limit effort="87" lower="-1.5707963267948966" upper="1.0471975511965976" velocity="2.3925"/>
  </joint>
  <transmission name="joint2_trans">
    <type>transmission_interface/SimpleTransmission</type>
    <joint name="joint2">
      <hardwareInterface>EffortJointInterface</hardwareInterface>
    </joint>
    <actuator name="joint2_actuator">
      <hardwareInterface>EffortJointInterface</hardwareInterface>
    </actuator>
  </transmission>
  <link name="link3">
    <visual>
      <origin rpy="0 0 0" xyz="0 0 0"/>
      <geometry>
        <mesh filename="package://drake/examples/hexapod_drake/mesh/Link3.obj"/>
      </geometry>
    </visual>
    <collision>
      <origin rpy="0 0 0" xyz="0 0 0"/>
      <geometry>
        <mesh filename="package://drake/examples/hexapod_drake/mesh/Link3.obj"/>
      </geometry>
    </collision>
    <inertial>
      <origin rpy="0 0 0" xyz="-9.052e-5 0.044 -0.03"/>
      <mass value="0.624"/>
      <inertia ixx="0.001966052" ixy="0" ixz="0" iyy="0.00108569" iyz="0.000898735" izz="0.001021702"/>
    </inertial>
  </link>
  <joint name="joint3" type="revolute">
    <origin rpy="-1.0471975511965976 0 0" xyz="0 0.0645 -0.0145"/>
    <parent link="link2"/>
    <child link="link3"/>
    <axis xyz="1 0 0"/>
    <limit effort="87" lower="-0.5235987755982988" upper="2.0943951023931953" velocity="2.3925"/>
  </joint>
  <transmission name="joint3_trans">
    <type>transmission_interface/SimpleTransmission</type>
    <joint name="joint3">
      <hardwareInterface>EffortJointInterface</hardwareInterface>
    </joint>
    <actuator name="joint3_actuator">
      <hardwareInterface>EffortJointInterface</hardwareInterface>
    </actuator>
  </transmission>
  <!--Leg 2 mid right-->
  <link name="link4">
    <visual>
      <origin rpy="0 0 0" xyz="0 0 0"/>
      <geometry>
        <mesh filename="package://drake/examples/hexapod_drake/mesh/Link1.obj"/>
      </geometry>
    </visual>
    <collision>
      <origin rpy="0 0 0" xyz="0 0 0"/>
      <geometry>
        <mesh filename="package://drake/examples/hexapod_drake/mesh/Link1.obj"/>
      </geometry>
    </collision>
    <inertial>
      <origin rpy="0 0 0" xyz="-5.5334e-4 0.026044272 5.74418e-4"/>
      <mass value="0.121"/>
      <inertia ixx="5.423e-5" ixy="0" ixz="0" iyy="4.8e-5" iyz="0" izz="5.426e-5"/>
    </inertial>
  </link>
  <joint name="joint4" type="revolute">
    <origin rpy="3.14 0 -1.5707963267948966" xyz="-0.117 0 0 "/>
    <parent link="body"/>
    <child link="link4"/>
    <axis xyz="0 0 1"/>
    <limit effort="87" lower="-1.0471975511965976" upper="1.0471975511965976" velocity="2.3925"/>
  </joint>
  <transmission name="joint4_trans">
    <type>transmission_interface/SimpleTransmission</type>
    <joint name="joint4">
      <hardwareInterface>EffortJointInterface</hardwareInterface>
    </joint>
    <actuator name="joint4_actuator">
      <hardwareInterface>EffortJointInterface</hardwareInterface>
    </actuator>
  </transmission>
  <link name="link5">
    <visual>
      <origin rpy="0 0 0" xyz="0 0 0"/>
      <geometry>
        <mesh filename="package://drake/examples/hexapod_drake/mesh/Link2.obj"/>
      </geometry>
    </visual>
    <collision>
      <origin rpy="0 0 0" xyz="0 0 0"/>
      <geometry>
        <mesh filename="package://drake/examples/hexapod_drake/mesh/Link2.obj"/>
      </geometry>
    </collision>
    <inertial>
      <origin rpy="0 0 0" xyz="-6.24554e-4 0.019941332 -6.17953e-4"/>
      <mass value="0.43"/>
      <inertia ixx="1.94195e-4" ixy="0" ixz="0" iyy="0.0000912" iyz="0" izz="2.29579e-4"/>
    </inertial>
  </link>
  <joint name="joint5" type="revolute">
    <origin rpy="0.5235987755982988 3.14 0" xyz="0 0.052 0"/>
    <parent link="link4"/>
    <child link="link5"/>
    <axis xyz="1 0 0"/>
    <limit effort="87" lower="-1.5707963267948966" upper="1.0471975511965976" velocity="2.3925"/>
  </joint>
  <transmission name="joint5_trans">
    <type>transmission_interface/SimpleTransmission</type>
    <joint name="joint5">
      <hardwareInterface>EffortJointInterface</hardwareInterface>
    </joint>
    <actuator name="joint5_actuator">
      <hardwareInterface>EffortJointInterface</hardwareInterface>
    </actuator>
  </transmission>
  <link name="link6">
    <visual>
      <origin rpy="0 0 0" xyz="0 0 0"/>
      <geometry>
        <mesh filename="package://drake/examples/hexapod_drake/mesh/Link3.obj"/>
      </geometry>
    </visual>
    <collision>
      <origin rpy="0 0 0" xyz="0 0 0"/>
      <geometry>
        <mesh filename="package://drake/examples/hexapod_drake/mesh/Link3.obj"/>
      </geometry>
    </collision>
    <inertial>
      <origin rpy="0 0 0" xyz="-9.052e-5 0.044 -0.03"/>
      <mass value="0.624"/>
      <inertia ixx="0.001966052" ixy="0" ixz="0" iyy="0.00108569" iyz="0.000898735" izz="0.001021702"/>
    </inertial>
  </link>
  <joint name="joint6" type="revolute">
    <origin rpy="-1.0471975511965976 0 0" xyz="0 0.0645 -0.0145"/>
    <parent link="link5"/>
    <child link="link6"/>
    <axis xyz="1 0 0"/>
    <limit effort="87" lower="-0.5235987755982988" upper="2.0943951023931953" velocity="2.3925"/>
  </joint>
  <transmission name="joint6_trans">
    <type>transmission_interface/SimpleTransmission</type>
    <joint name="joint6">
      <hardwareInterface>EffortJointInterface</hardwareInterface>
    </joint>
    <actuator name="joint6_actuator">
      <hardwareInterface>EffortJointInterface</hardwareInterface>
    </actuator>
  </transmission>
  <!--Leg 3 back right-->
  <link name="link7">
    <visual>
      <origin rpy="0 0 0" xyz="0 0 0"/>
      <geometry>
        <mesh filename="package://drake/examples/hexapod_drake/mesh/Link1.obj"/>
      </geometry>
    </visual>
    <collision>
      <origin rpy="0 0 0" xyz="0 0 0"/>
      <geometry>
        <mesh filename="package://drake/examples/hexapod_drake/mesh/Link1.obj"/>
      </geometry>
    </collision>
    <inertial>
      <origin rpy="0 0 0" xyz="-5.5334e-4 0.026044272 5.74418e-4"/>
      <mass value="0.121"/>
      <inertia ixx="5.423e-5" ixy="0" ixz="0" iyy="4.8e-5" iyz="0" izz="5.426e-5"/>
    </inertial>
  </link>
  <joint name="joint7" type="revolute">
    <origin rpy="3.14 0 -2.35619" xyz="-0.07591 0.14091 0 "/>
    <parent link="body"/>
    <child link="link7"/>
    <axis xyz="0 0 1"/>
    <limit effort="87" lower="-1.0471975511965976" upper="1.0471975511965976" velocity="2.3925"/>
  </joint>
  <transmission name="joint7_trans">
    <type>transmission_interface/SimpleTransmission</type>
    <joint name="joint7">
      <hardwareInterface>EffortJointInterface</hardwareInterface>
    </joint>
    <actuator name="joint7_actuator">
      <hardwareInterface>EffortJointInterface</hardwareInterface>
    </actuator>
  </transmission>
  <link name="link8">
    <visual>
      <origin rpy="0 0 0" xyz="0 0 0"/>
      <geometry>
        <mesh filename="package://drake/examples/hexapod_drake/mesh/Link2.obj"/>
      </geometry>
    </visual>
    <collision>
      <origin rpy="0 0 0" xyz="0 0 0"/>
      <geometry>
        <mesh filename="package://drake/examples/hexapod_drake/mesh/Link2.obj"/>
      </geometry>
    </collision>
    <inertial>
      <origin rpy="0 0 0" xyz="-6.24554e-4 0.019941332 -6.17953e-4"/>
      <mass value="0.43"/>
      <inertia ixx="1.94195e-4" ixy="0" ixz="0" iyy="0.0000912" iyz="0" izz="2.29579e-4"/>
    </inertial>
  </link>
  <joint name="joint8" type="revolute">
    <origin rpy="0.5235987755982988 3.14 0" xyz="0 0.052 0"/>
    <parent link="link7"/>
    <child link="link8"/>
    <axis xyz="1 0 0"/>
    <limit effort="87" lower="-1.5707963267948966" upper="1.0471975511965976" velocity="2.3925"/>
  </joint>
  <transmission name="joint8_trans">
    <type>transmission_interface/SimpleTransmission</type>
    <joint name="joint8">
      <hardwareInterface>EffortJointInterface</hardwareInterface>
    </joint>
    <actuator name="joint8_actuator">
      <hardwareInterface>EffortJointInterface</hardwareInterface>
    </actuator>
  </transmission>
  <link name="link9">
    <visual>
      <origin rpy="0 0 0" xyz="0 0 0"/>
      <geometry>
        <mesh filename="package://drake/examples/hexapod_drake/mesh/Link3.obj"/>
      </geometry>
    </visual>
    <collision>
      <origin rpy="0 0 0" xyz="0 0 0"/>
      <geometry>
        <mesh filename="package://drake/examples/hexapod_drake/mesh/Link3.obj"/>
      </geometry>
    </collision>
    <inertial>
      <origin rpy="0 0 0" xyz="-9.052e-5 0.044 -0.03"/>
      <mass value="0.624"/>
      <inertia ixx="0.001966052" ixy="0" ixz="0" iyy="0.00108569" iyz="0.000898735" izz="0.001021702"/>
    </inertial>
  </link>
  <joint name="joint9" type="revolute">
    <origin rpy="-1.0471975511965976 0 0" xyz="0 0.0645 -0.0145"/>
    <parent link="link8"/>
    <child link="link9"/>
    <axis xyz="1 0 0"/>
    <limit effort="87" lower="-0.5235987755982988" upper="2.0943951023931953" velocity="2.3925"/>
  </joint>
  <transmission name="joint9_trans">
    <type>transmission_interface/SimpleTransmission</type>
    <joint name="joint9">
      <hardwareInterface>EffortJointInterface</hardwareInterface>
    </joint>
    <actuator name="joint9_actuator">
      <hardwareInterface>EffortJointInterface</hardwareInterface>
    </actuator>
  </transmission>
  <!--Leg 4 front left-->
  <link name="link10">
    <visual>
      <origin rpy="0 0 0" xyz="0 0 0"/>
      <geometry>
        <mesh filename="package://drake/examples/hexapod_drake/mesh/Link1.obj"/>
      </geometry>
    </visual>
    <collision>
      <origin rpy="0 0 0" xyz="0 0 0"/>
      <geometry>
        <mesh filename="package://drake/examples/hexapod_drake/mesh/Link1.obj"/>
      </geometry>
    </collision>
    <inertial>
      <origin rpy="0 0 0" xyz="-5.5334e-4 0.026044272 5.74418e-4"/>
      <mass value="0.121"/>
      <inertia ixx="5.423e-5" ixy="0" ixz="0" iyy="4.8e-5" iyz="0" izz="5.426e-5"/>
    </inertial>
  </link>
  <joint name="joint10" type="revolute">
    <origin rpy="3.14 0 0.78699" xyz="0.07591 -0.14091 0 "/>
    <parent link="body"/>
    <child link="link10"/>
    <axis xyz="0 0 1"/>
    <limit effort="87" lower="-1.0471975511965976" upper="1.0471975511965976" velocity="2.3925"/>
  </joint>
  <transmission name="joint10_trans">
    <type>transmission_interface/SimpleTransmission</type>
    <joint name="joint10">
      <hardwareInterface>EffortJointInterface</hardwareInterface>
    </joint>
    <actuator name="joint10_actuator">
      <hardwareInterface>EffortJointInterface</hardwareInterface>
    </actuator>
  </transmission>
  <link name="link11">
    <visual>
      <origin rpy="0 0 0" xyz="0 0 0"/>
      <geometry>
        <mesh filename="package://drake/examples/hexapod_drake/mesh/Link2.obj"/>
      </geometry>
    </visual>
    <collision>
      <origin rpy="0 0 0" xyz="0 0 0"/>
      <geometry>
        <mesh filename="package://drake/examples/hexapod_drake/mesh/Link2.obj"/>
      </geometry>
    </collision>
    <inertial>
      <origin rpy="0 0 0" xyz="-6.24554e-4 0.019941332 -6.17953e-4"/>
      <mass value="0.43"/>
      <inertia ixx="1.94195e-4" ixy="0" ixz="0" iyy="0.0000912" iyz="0" izz="2.29579e-4"/>
    </inertial>
  </link>
  <joint name="joint11" type="revolute">
    <origin rpy="0.5235987755982988 3.14 0" xyz="0 0.052 0"/>
    <parent link="link10"/>
    <child link="link11"/>
    <axis xyz="1 0 0"/>
    <limit effort="87" lower="-1.5707963267948966" upper="1.0471975511965976" velocity="2.3925"/>
  </joint>
  <transmission name="joint11_trans">
    <type>transmission_interface/SimpleTransmission</type>
    <joint name="joint11">
      <hardwareInterface>EffortJointInterface</hardwareInterface>
    </joint>
    <actuator name="joint11_actuator">
      <hardwareInterface>EffortJointInterface</hardwareInterface>
    </actuator>
  </transmission>
  <link name="link12">
    <visual>
      <origin rpy="0 0 0" xyz="0 0 0"/>
      <geometry>
        <mesh filename="package://drake/examples/hexapod_drake/mesh/Link3.obj"/>
      </geometry>
    </visual>
    <collision>
      <origin rpy="0 0 0" xyz="0 0 0"/>
      <geometry>
        <mesh filename="package://drake/examples/hexapod_drake/mesh/Link3.obj"/>
      </geometry>
    </collision>
    <inertial>
      <origin rpy="0 0 0" xyz="-9.052e-5 0.044 -0.03"/>
      <mass value="0.624"/>
      <inertia ixx="0.001966052" ixy="0" ixz="0" iyy="0.00108569" iyz="0.000898735" izz="0.001021702"/>
    </inertial>
  </link>
  <joint name="joint12" type="revolute">
    <origin rpy="-1.0471975511965976 0 0" xyz="0 0.0645 -0.0145"/>
    <parent link="link11"/>
    <child link="link12"/>
    <axis xyz="1 0 0"/>
    <limit effort="87" lower="-0.5235987755982988" upper="2.0943951023931953" velocity="2.3925"/>
  </joint>
  <transmission name="joint12_trans">
    <type>transmission_interface/SimpleTransmission</type>
    <joint name="joint12">
      <hardwareInterface>EffortJointInterface</hardwareInterface>
    </joint>
    <actuator name="joint12_actuator">
      <hardwareInterface>EffortJointInterface</hardwareInterface>
    </actuator>
  </transmission>
  <!--Leg 5 mid left-->
  <link name="link13">
    <visual>
      <origin rpy="0 0 0" xyz="0 0 0"/>
      <geometry>
        <mesh filename="package://drake/examples/hexapod_drake/mesh/Link1.obj"/>
      </geometry>
    </visual>
    <collision>
      <origin rpy="0 0 0" xyz="0 0 0"/>
      <geometry>
        <mesh filename="package://drake/examples/hexapod_drake/mesh/Link1.obj"/>
      </geometry>
    </collision>
    <inertial>
      <origin rpy="0 0 0" xyz="-5.5334e-4 0.026044272 5.74418e-4"/>
      <mass value="0.121"/>
      <inertia ixx="5.423e-5" ixy="0" ixz="0" iyy="4.8e-5" iyz="0" izz="5.426e-5"/>
    </inertial>
  </link>
  <joint name="joint13" type="revolute">
    <origin rpy="3.14 0 1.57" xyz="0.117 0 0 "/>
    <parent link="body"/>
    <child link="link13"/>
    <axis xyz="0 0 1"/>
    <limit effort="87" lower="-1.0471975511965976" upper="1.0471975511965976" velocity="2.3925"/>
  </joint>
  <transmission name="joint13_trans">
    <type>transmission_interface/SimpleTransmission</type>
    <joint name="joint13">
      <hardwareInterface>EffortJointInterface</hardwareInterface>
    </joint>
    <actuator name="joint13_actuator">
      <hardwareInterface>EffortJointInterface</hardwareInterface>
    </actuator>
  </transmission>
  <link name="link14">
    <visual>
      <origin rpy="0 0 0" xyz="0 0 0"/>
      <geometry>
        <mesh filename="package://drake/examples/hexapod_drake/mesh/Link2.obj"/>
      </geometry>
    </visual>
    <collision>
      <origin rpy="0 0 0" xyz="0 0 0"/>
      <geometry>
        <mesh filename="package://drake/examples/hexapod_drake/mesh/Link2.obj"/>
      </geometry>
    </collision>
    <inertial>
      <origin rpy="0 0 0" xyz="-6.24554e-4 0.019941332 -6.17953e-4"/>
      <mass value="0.43"/>
      <inertia ixx="1.94195e-4" ixy="0" ixz="0" iyy="0.0000912" iyz="0" izz="2.29579e-4"/>
    </inertial>
  </link>
  <joint name="joint14" type="revolute">
    <origin rpy="0.5235987755982988 3.14 0" xyz="0 0.052 0"/>
    <parent link="link13"/>
    <child link="link14"/>
    <axis xyz="1 0 0"/>
    <limit effort="87" lower="-1.5707963267948966" upper="1.0471975511965976" velocity="2.3925"/>
  </joint>
  <transmission name="joint14_trans">
    <type>transmission_interface/SimpleTransmission</type>
    <joint name="joint14">
      <hardwareInterface>EffortJointInterface</hardwareInterface>
    </joint>
    <actuator name="joint14_actuator">
      <hardwareInterface>EffortJointInterface</hardwareInterface>
    </actuator>
  </transmission>
  <link name="link15">
    <visual>
      <origin rpy="0 0 0" xyz="0 0 0"/>
      <geometry>
        <mesh filename="package://drake/examples/hexapod_drake/mesh/Link3.obj"/>
      </geometry>
    </visual>
    <collision>
      <origin rpy="0 0 0" xyz="0 0 0"/>
      <geometry>
        <mesh filename="package://drake/examples/hexapod_drake/mesh/Link3.obj"/>
      </geometry>
    </collision>
    <inertial>
      <origin rpy="0 0 0" xyz="-9.052e-5 0.044 -0.03"/>
      <mass value="0.624"/>
      <inertia ixx="0.001966052" ixy="0" ixz="0" iyy="0.00108569" iyz="0.000898735" izz="0.001021702"/>
    </inertial>
  </link>
  <joint name="joint15" type="revolute">
    <origin rpy="-1.0471975511965976 0 0" xyz="0 0.0645 -0.0145"/>
    <parent link="link14"/>
    <child link="link15"/>
    <axis xyz="1 0 0"/>
    <limit effort="87" lower="-0.5235987755982988" upper="2.0943951023931953" velocity="2.3925"/>
  </joint>
  <transmission name="joint15_trans">
    <type>transmission_interface/SimpleTransmission</type>
    <joint name="joint15">
      <hardwareInterface>EffortJointInterface</hardwareInterface>
    </joint>
    <actuator name="joint15_actuator">
      <hardwareInterface>EffortJointInterface</hardwareInterface>
    </actuator>
  </transmission>
  <!--Leg 6 back left-->
  <link name="link16">
    <visual>
      <origin rpy="0 0 0" xyz="0 0 0"/>
      <geometry>
        <mesh filename="package://drake/examples/hexapod_drake/mesh/Link1.obj"/>
      </geometry>
    </visual>
    <collision>
      <origin rpy="0 0 0" xyz="0 0 0"/>
      <geometry>
        <mesh filename="package://drake/examples/hexapod_drake/mesh/Link1.obj"/>
      </geometry>
    </collision>
    <inertial>
      <origin rpy="0 0 0" xyz="-5.5334e-4 0.026044272 5.74418e-4"/>
      <mass value="0.121"/>
      <inertia ixx="5.423e-5" ixy="0" ixz="0" iyy="4.8e-5" iyz="0" izz="5.426e-5"/>
    </inertial>
  </link>
  <joint name="joint16" type="revolute">
    <origin rpy="3.14 0 2.3546018366" xyz="0.07591 0.14091 0 "/>
    <parent link="body"/>
    <child link="link16"/>
    <axis xyz="0 0 1"/>
    <limit effort="87" lower="-1.0471975511965976" upper="1.0471975511965976" velocity="2.3925"/>
  </joint>
  <transmission name="joint16_trans">
    <type>transmission_interface/SimpleTransmission</type>
    <joint name="joint16">
      <hardwareInterface>EffortJointInterface</hardwareInterface>
    </joint>
    <actuator name="joint16_actuator">
      <hardwareInterface>EffortJointInterface</hardwareInterface>
    </actuator>
  </transmission>
  <link name="link17">
    <visual>
      <origin rpy="0 0 0" xyz="0 0 0"/>
      <geometry>
        <mesh filename="package://drake/examples/hexapod_drake/mesh/Link2.obj"/>
      </geometry>
    </visual>
    <collision>
      <origin rpy="0 0 0" xyz="0 0 0"/>
      <geometry>
        <mesh filename="package://drake/examples/hexapod_drake/mesh/Link2.obj"/>
      </geometry>
    </collision>
    <inertial>
      <origin rpy="0 0 0" xyz="-6.24554e-4 0.019941332 -6.17953e-4"/>
      <mass value="0.43"/>
      <inertia ixx="1.94195e-4" ixy="0" ixz="0" iyy="0.0000912" iyz="0" izz="2.29579e-4"/>
    </inertial>
  </link>
  <joint name="joint17" type="revolute">
    <origin rpy="0.5235987755982988 3.14 0" xyz="0 0.052 0"/>
    <parent link="link16"/>
    <child link="link17"/>
    <axis xyz="1 0 0"/>
    <limit effort="87" lower="-1.5707963267948966" upper="1.0471975511965976" velocity="2.3925"/>
  </joint>
  <transmission name="joint17_trans">
    <type>transmission_interface/SimpleTransmission</type>
    <joint name="joint17">
      <hardwareInterface>EffortJointInterface</hardwareInterface>
    </joint>
    <actuator name="joint17_actuator">
      <hardwareInterface>EffortJointInterface</hardwareInterface>
    </actuator>
  </transmission>
  <link name="link18">
    <visual>
      <origin rpy="0 0 0" xyz="0 0 0"/>
      <geometry>
        <mesh filename="package://drake/examples/hexapod_drake/mesh/Link3.obj"/>
      </geometry>
    </visual>
    <collision>
      <origin rpy="0 0 0" xyz="0 0 0"/>
      <geometry>
        <mesh filename="package://drake/examples/hexapod_drake/mesh/Link3.obj"/>
      </geometry>
    </collision>
    <inertial>
      <origin rpy="0 0 0" xyz="-9.052e-5 0.044 -0.03"/>
      <mass value="0.624"/>
      <inertia ixx="0.001966052" ixy="0" ixz="0" iyy="0.00108569" iyz="0.000898735" izz="0.001021702"/>
    </inertial>
  </link>
  <joint name="joint18" type="revolute">
    <origin rpy="-1.0471975511965976 0 0" xyz="0 0.0645 -0.0145"/>
    <parent link="link17"/>
    <child link="link18"/>
    <axis xyz="1 0 0"/>
    <limit effort="87" lower="-0.5235987755982988" upper="2.0943951023931953" velocity="2.3925"/>
  </joint>
  <transmission name="joint18_trans">
    <type>transmission_interface/SimpleTransmission</type>
    <joint name="joint18">
      <hardwareInterface>EffortJointInterface</hardwareInterface>
    </joint>
    <actuator name="joint18_actuator">
      <hardwareInterface>EffortJointInterface</hardwareInterface>
    </actuator>
  </transmission>
</robot>
